<?xml version="1.0" ?>
<!-- =================================================================================== -->
<!-- |    This document was autogenerated by xacro from robot.xacro                    | -->
<!-- |    EDITING THIS FILE BY HAND IS NOT RECOMMENDED                                 | -->
<!-- =================================================================================== -->
<robot name="my_biped_description">
  <material name="black">
    <color rgba="0.0 0.0 0.0 1.0"/>
  </material>
  <material name="blue">
    <color rgba="0.0 0.0 0.8 1.0"/>
  </material>
  <material name="green">
    <color rgba="0.0 0.8 0.0 1.0"/>
  </material>
  <material name="grey">
    <color rgba="0.2 0.2 0.2 1.0"/>
  </material>
  <material name="silver">
    <color rgba="0.9137254901960784 0.9137254901960784 0.8470588235294118 1.0"/>
  </material>
  <material name="orange">
    <color rgba="1.0 0.4235294117647059 0.0392156862745098 1.0"/>
  </material>
  <material name="brown">
    <color rgba="0.8705882352941177 0.8117647058823529 0.7647058823529411 1.0"/>
  </material>
  <material name="red">
    <color rgba="0.8 0.0 0.0 1.0"/>
  </material>
  <material name="white">
    <color rgba="1.0 1.0 1.0 1.0"/>
  </material>
  <!-- ros_control plugin -->
  <gazebo>
    <plugin filename="libgazebo_ros_control.so" name="gazebo_ros_control">
      <robotNamespace>/laikago_gazebo</robotNamespace>
      <robotSimType>gazebo_ros_control/DefaultRobotHWSim</robotSimType>
    </plugin>
  </gazebo>
  <!-- Show the trajectory of trunk center. -->
  <gazebo>
    <plugin filename="libLinkPlot3DPlugin.so" name="3dplot">
      <frequency>10</frequency>
      <plot>
        <link>base</link>
        <pose>0 0 0 0 0 0</pose>
        <material>Gazebo/Yellow</material>
      </plot>
    </plugin>
  </gazebo>
  <!-- Show the trajectory of foot. You can add another trajectory about another foot. -->
  <!-- <gazebo>
        <plugin name="3dplot" filename="libLinkPlot3DPlugin.so">
            <frequency>100</frequency>
            <plot>
                <link>FL_foot</link>
                <pose>0 0 0 0 0 0</pose>
                <material>Gazebo/Green</material>
            </plot>
        </plugin>
    </gazebo> -->
  <gazebo>
    <plugin filename="libgazebo_ros_force.so" name="gazebo_ros_force">
      <bodyName>trunk</bodyName>
      <topicName>/apply_force/trunk</topicName>
    </plugin>
  </gazebo>
  <gazebo reference="imu_link">
    <gravity>true</gravity>
    <sensor name="imu_sensor" type="imu">
      <always_on>true</always_on>
      <update_rate>1000</update_rate>
      <visualize>true</visualize>
      <topic>__default_topic__</topic>
      <plugin filename="libgazebo_ros_imu_sensor.so" name="imu_plugin">
        <topicName>trunk_imu</topicName>
        <bodyName>imu_link</bodyName>
        <updateRateHZ>1000.0</updateRateHZ>
        <gaussianNoise>0.002</gaussianNoise>
        <xyzOffset>0 0 0</xyzOffset>
        <rpyOffset>0 0 0</rpyOffset>
        <frameName>imu_link</frameName>
      </plugin>
      <pose>0 0 0 0 0 0</pose>
    </sensor>
  </gazebo>
  <gazebo reference="base">
    <material>Gazebo/Green</material>
    <turnGravityOff>false</turnGravityOff>
  </gazebo>
  <gazebo reference="trunk">
    <mu1>0.2</mu1>
    <mu2>0.2</mu2>
    <material>Gazebo/DarkGrey</material>
  </gazebo>
  <gazebo reference="trunkcol">
    <mu1>0.2</mu1>
    <mu2>0.2</mu2>
  </gazebo>
  <!--<gazebo reference="support">
        <mu1>0.1</mu1>
        <mu2>0.1</mu2>
        <self_collide>1</self_collide>
    </gazebo>-->
  <gazebo reference="stick_link">
    <mu1>0.2</mu1>
    <mu2>0.2</mu2>
    <material>Gazebo/White</material>
  </gazebo>
  <gazebo reference="imu_link">
    <mu1>1</mu1>
    <mu2>1</mu2>
    <material>Gazebo/Red</material>
  </gazebo>
  <!-- L leg -->
  <gazebo reference="L_hip">
    <mu1>1</mu1>
    <mu2>1</mu2>
    <kp value="100000.0"/>
    <kd value="1000.0"/>
    <material>Gazebo/DarkGrey</material>
  </gazebo>
  <gazebo reference="L_hip2">
    <mu1>1</mu1>
    <mu2>1</mu2>
    <kp value="100000.0"/>
    <kd value="1000.0"/>
    <material>Gazebo/Red</material>
  </gazebo>
  <gazebo reference="L_thigh">
    <mu1>1</mu1>
    <mu2>1</mu2>
    <kp value="100000.0"/>
    <kd value="1000.0"/>
    <self_collide>1</self_collide>
    <material>Gazebo/DarkGrey</material>
  </gazebo>
  <gazebo reference="L_calf">
    <mu1>1</mu1>
    <mu2>1</mu2>
    <kp value="100000.0"/>
    <kd value="1000.0"/>
    <self_collide>1</self_collide>
  </gazebo>
  <gazebo reference="L_toe">
    <mu1>1</mu1>
    <mu2>1</mu2>
    <kp value="100000.0"/>
    <kd value="1000.0"/>
    <self_collide>1</self_collide>
    <material>Gazebo/DarkGrey</material>
  </gazebo>
  <!--R leg -->
  <gazebo reference="R_hip">
    <mu1>1</mu1>
    <mu2>1</mu2>
    <kp value="100000.0"/>
    <kd value="1000.0"/>
    <material>Gazebo/DarkGrey</material>
  </gazebo>
  <gazebo reference="R_hip2">
    <mu1>1</mu1>
    <mu2>1</mu2>
    <kp value="100000.0"/>
    <kd value="1000.0"/>
    <material>Gazebo/Red</material>
  </gazebo>
  <gazebo reference="R_thigh">
    <mu1>1</mu1>
    <mu2>1</mu2>
    <kp value="100000.0"/>
    <kd value="1000.0"/>
    <self_collide>1</self_collide>
    <material>Gazebo/DarkGrey</material>
  </gazebo>
  <gazebo reference="R_calf">
    <mu1>1</mu1>
    <mu2>1</mu2>
    <kp value="100000.0"/>
    <kd value="1000.0"/>
    <self_collide>1</self_collide>
  </gazebo>
  <gazebo reference="R_toe">
    <mu1>1</mu1>
    <mu2>1</mu2>
    <kp value="100000.0"/>
    <kd value="1000.0"/>
    <self_collide>1</self_collide>
    <material>Gazebo/DarkGrey</material>
  </gazebo>
  <!-- <xacro:include filename="$(find a1_gazebo)/launch/stairs.urdf.xacro"/> -->
  <!-- <xacro:stairs stairs="15" xpos="0" ypos="0" zpos="0" /> -->
  <!-- Debug mode will hung up the robot, use "true" or "false" to switch it.
    <xacro:if value="$(arg DEBUG)">
        <link name="world"/>
        <joint name="base_static_joint" type="fixed">
            <origin rpy="0 0 0" xyz="0 0 0"/>
            <parent link="world"/>
            <child link="base"/>
        </joint>
    </xacro:if> -->
  <link name="world">
    <visual>
      <origin rpy="0 0 0" xyz="0 0 0"/>
      <geometry>
        <box size="0.001 0.001 0.001"/>
      </geometry>
    </visual>
  </link>
  <joint name="floating_base" type="fixed">
    <origin rpy="0 0 0" xyz="0 0 0"/>
    <parent link="world"/>
    <child link="trunk"/>
  </joint>
  <link name="trunk">
    <visual>
      <origin rpy="0 0 0" xyz="0 0 0"/>
      <geometry>
        <mesh filename="package://my_biped_description/meshes/body.STL" scale="1 1 1"/>
      </geometry>
      <material name="white"/>
    </visual>
    <collision>
      <origin rpy="0 0 0" xyz="0 0 0"/>
      <geometry>
        <box size="0.125 0.19 0.248"/>
      </geometry>
    </collision>
    <inertial>
      <origin rpy="0 0 0" xyz="0.0 0.0 0.0"/>
      <mass value="5.7"/>
      <inertia ixx="0.0463619" ixy="0.0" ixz="0.0" iyy="0.036636" iyz="0.0" izz="0.024569"/>
    </inertial>
  </link>
  <joint name="imu_joint" type="fixed">
    <parent link="trunk"/>
    <child link="imu_link"/>
    <origin rpy="0 0 0" xyz="0 0 0"/>
  </joint>
  <link name="imu_link">
    <inertial>
      <mass value="0.001"/>
      <origin rpy="0 0 0" xyz="0 0 0"/>
      <inertia ixx="0.0001" ixy="0" ixz="0" iyy="0.0001" iyz="0" izz="0.0001"/>
    </inertial>
    <visual>
      <origin rpy="0 0 0" xyz="0 0 0"/>
      <geometry>
        <box size="0.001 0.001 0.001"/>
      </geometry>
      <material name="red"/>
    </visual>
    <collision>
      <origin rpy="0 0 0" xyz="0 0 0"/>
      <geometry>
        <box size=".001 .001 .001"/>
      </geometry>
    </collision>
  </link>
  <joint name="L_hip_joint" type="revolute">
    <origin rpy="0 0 0" xyz="0.0 0.047 -0.1265"/>
    <parent link="trunk"/>
    <child link="L_hip"/>
    <axis xyz="0 0 1"/>
    <dynamics damping="0.1" friction="0.1"/>
    <limit effort="33.5" lower="-0.2617993877991494" upper="0.2617993877991494" velocity="21"/>
  </joint>
  <link name="L_hip">
    <visual>
      <origin rpy="0 0 0" xyz="0 0 0"/>
      <geometry>
        <mesh filename="package://my_biped_description/meshes/L_hip1.STL" scale="1 1 1"/>
      </geometry>
      <material name="orange"/>
    </visual>
    <collision>
      <origin rpy="0 0 0" xyz="0.015 0.0 -0.002"/>
      <geometry>
        <box size="0.0001 0.0001 0.0001"/>
      </geometry>
    </collision>
    <inertial>
      <origin rpy="0 0 0" xyz="0.025109 -0.002292 -0.024732"/>
      <mass value="0.224"/>
      <inertia ixx="2.104e-06" ixy="0.0" ixz="0.0" iyy="5.354e-06" iyz="0.0" izz="7.416e-06"/>
    </inertial>
  </link>
  <!--this link is only for motor mass&colllision-->
  <joint name="L_hip_trans_joint" type="fixed">
    <origin rpy="0 0 0" xyz="0.079 0.015 -0.0705"/>
    <parent link="L_hip"/>
    <child link="L_hip_trans"/>
  </joint>
   --&gt;


  <link name="L_hip_trans">
    <collision>
      <origin rpy="0 1.5707963267948966 0" xyz="0 0 0"/>
      <geometry>
        <cylinder length="0.04" radius="0.045"/>
      </geometry>
    </collision>
    <inertial>
      <origin rpy="0 0 0" xyz="0 0 0"/>
      <mass value="0.65"/>
      <inertia ixx="0.00043875" ixy="0.0" ixz="0.0" iyy="0.00043875" iyz="0.0" izz="0.000658125"/>
    </inertial>
  </link>
  <joint name="L_hip2_joint" type="revolute">
    <origin rpy="0 0 0" xyz="0.0465 0.015 -0.0705"/>
    <parent link="L_hip"/>
    <child link="L_hip2"/>
    <axis xyz="1 0 0"/>
    <dynamics damping="0.1" friction="0.1"/>
    <limit effort="33.5" lower="-0.5235987755982988" upper="0.2617993877991494" velocity="21"/>
  </joint>
  <link name="L_hip2">
    <visual>
      <origin rpy="0 0 0" xyz="0 0 0"/>
      <geometry>
        <mesh filename="package://my_biped_description/meshes/L_hip2.STL" scale="1 1 1"/>
      </geometry>
      <material name="red"/>
    </visual>
    <collision>
      <origin rpy="0 0 0" xyz="-0.1 0 0"/>
      <geometry>
        <box size="1e-05 1e-05 1e-05"/>
      </geometry>
    </collision>
    <inertial>
      <origin rpy="0 0 0" xyz="-0.033217 -0.010231 0"/>
      <mass value="0.095"/>
      <inertia ixx="5.1083e-05" ixy="0.0" ixz="0.0" iyy="1.39825e-05" iyz="0.0" izz="9.3473e-05"/>
    </inertial>
  </link>
  <!--this link is only for collision-->
  <joint name="L_hip2_trans_joint" type="fixed">
    <origin rpy="0 0 0" xyz="-0.06 -0.015 0.0"/>
    <parent link="L_hip2"/>
    <child link="L_hip2_trans"/>
  </joint>
  <link name="L_hip2_trans">
    <collision>
      <origin rpy="-1.5707963267948966 0 0" xyz="0 0 0"/>
      <geometry>
        <cylinder length="0.04" radius="0.045"/>
      </geometry>
    </collision>
    <inertial>
      <origin rpy="-1.5707963267948966 0 0" xyz="0 0 0"/>
      <mass value="0.65"/>
      <inertia ixx="0.00043875" ixy="0.0" ixz="0.0" iyy="0.00043875" iyz="0.0" izz="0.000658125"/>
    </inertial>
  </link>
  <joint name="L_thigh_joint" type="revolute">
    <origin rpy="0 0.9424777960769379 0" xyz="-0.06 0.018 0"/>
    <parent link="L_hip2"/>
    <child link="L_thigh"/>
    <axis xyz="0 1 0"/>
    <joint_properties damping="0.1" friction="0.1"/>
    <!-- <limit effort="${thigh_torque_max}" velocity="${thigh_velocity_max}"/> -->
    <limit effort="33.5" lower="-3.14" upper="3.14" velocity="21"/>
  </joint>
  <link name="L_thigh">
    <visual>
      <origin rpy="0 0 0" xyz="0 0 0"/>
      <geometry>
        <mesh filename="package://my_biped_description/meshes/L_thigh.STL" scale="1 1 1"/>
      </geometry>
      <material name="white"/>
    </visual>
    <collision>
      <origin rpy="0 0 0" xyz="0.0 0.0175 -0.09"/>
      <geometry>
        <box size="0.06 0.035 0.18"/>
      </geometry>
    </collision>
    <inertial>
      <origin rpy="0 0 0" xyz="-0.000147 0.01991 -0.081117"/>
      <mass value="0.642"/>
      <inertia ixx="0.004437615" ixy="0.0" ixz="0.0" iyy="0.004788512" iyz="0.0" izz="0.000661818"/>
    </inertial>
  </link>
  <!--this link is only for collision-->
  <joint name="L_thigh1_trans_joint" type="fixed">
    <origin rpy="0 0 0" xyz="0.0 0.0625 0.0"/>
    <parent link="L_thigh"/>
    <child link="L_thigh1_trans"/>
  </joint>
    --&gt;


  <link name="L_thigh1_trans">
    <collision>
      <origin rpy="-1.5707963267948966 0 0" xyz="0 0 0"/>
      <geometry>
        <cylinder length="0.04" radius="0.045"/>
      </geometry>
    </collision>
    <inertial>
      <origin rpy="-1.5707963267948966 0 0" xyz="0 0 0"/>
      <mass value="0.65"/>
      <inertia ixx="0.00043875" ixy="0.0" ixz="0.0" iyy="0.00043875" iyz="0.0" izz="0.000658125"/>
    </inertial>
  </link>
  <!--this link is only for collision-->
  <joint name="L_thigh2_trans_joint" type="fixed">
    <origin rpy="0 0 0" xyz="0.0 -0.0225 -0.097"/>
    <parent link="L_thigh"/>
    <child link="L_thigh2_trans"/>
  </joint>
  <link name="L_thigh2_trans">
    <collision>
      <origin rpy="-1.5707963267948966 0 0" xyz="0 0 0"/>
      <geometry>
        <cylinder length="0.04" radius="0.045"/>
      </geometry>
    </collision>
    <inertial>
      <origin rpy="-1.5707963267948966 0 0" xyz="0 0 0"/>
      <mass value="0.65"/>
      <inertia ixx="0.00043875" ixy="0.0" ixz="0.0" iyy="0.00043875" iyz="0.0" izz="0.000658125"/>
    </inertial>
  </link>
  <joint name="L_calf_joint" type="revolute">
    <origin rpy="0 -1.8849555921538759 0" xyz="0.0 0.0 -0.22"/>
    <parent link="L_thigh"/>
    <child link="L_calf"/>
    <axis xyz="0 1 0"/>
    <joint_properties damping="0.1" friction="0.1"/>
    <!-- <limit effort="${calf_torque_max}" velocity="${calf_velocity_max}"/> -->
    <limit effort="33.5" lower="-3.14" upper="3.14" velocity="21"/>
  </joint>
  <link name="L_calf">
    <visual>
      <origin rpy="0 0 0" xyz="0 0 0"/>
      <geometry>
        <mesh filename="package://my_biped_description/meshes/L_calf.STL" scale="1 1 1"/>
        <!-- <mesh filename="package://my_biped_description/meshes_new/left calf link.STL" scale="1 1 1"/> -->
      </geometry>
      <material name="orange"/>
    </visual>
    <collision>
      <origin rpy="0 0 0" xyz="0.0 0.02 -0.11"/>
      <geometry>
        <cylinder length="0.2" radius="0.015"/>
      </geometry>
    </collision>
    <inertial>
      <origin rpy="0 0 0" xyz="0.0 0.020417 -0.1141"/>
      <mass value="0.303"/>
      <inertia ixx="0.001911" ixy="0.0" ixz="0.0" iyy="0.00191038" iyz="0.0" izz="6.8352e-05"/>
    </inertial>
  </link>
  <joint name="L_toe_joint" type="revolute">
    <origin rpy="0 0.9424777960769379 0" xyz="0.0 0.0 -0.22"/>
    <parent link="L_calf"/>
    <child link="L_toe"/>
    <axis xyz="0 1 0"/>
    <joint_properties damping="0.1" friction="0.1"/>
    <!-- <limit effort="${toe_torque_max}" velocity="${toe_velocity_max}"/> -->
    <limit effort="33.5" lower="-1.4" upper="1.4" velocity="21"/>
  </joint>
  <link name="L_toe">
    <visual>
      <origin rpy="0 0 0" xyz="0 0 0"/>
      <geometry>
        <mesh filename="package://my_biped_description/meshes/L_foot.STL" scale="1 1 1"/>
      </geometry>
      <material name="red"/>
    </visual>
    <collision>
      <origin rpy="0 0 0" xyz="0.01 0.0194 -0.02"/>
      <geometry>
        <box size="0.15 0.02 0.04"/>
      </geometry>
    </collision>
    <inertial>
      <origin rpy="0 0 0" xyz="0.010569 0.017949 -0.017118"/>
      <mass value="0.214"/>
      <inertia ixx="5.7298e-05" ixy="0.0" ixz="0.0" iyy="0.000290752" iyz="0.0" izz="0.000249491"/>
    </inertial>
  </link>
  <transmission name="L_hip_tran">
    <type>transmission_interface/SimpleTransmission</type>
    <joint name="L_hip_joint">
      <hardwareInterface>hardware_interface/EffortJointInterface</hardwareInterface>
    </joint>
    <actuator name="L_hip_motor">
      <hardwareInterface>hardware_interface/EffortJointInterface</hardwareInterface>
      <mechanicalReduction>1</mechanicalReduction>
    </actuator>
  </transmission>
  <transmission name="L_hip2_tran">
    <type>transmission_interface/SimpleTransmission</type>
    <joint name="L_hip2_joint">
      <hardwareInterface>hardware_interface/EffortJointInterface</hardwareInterface>
    </joint>
    <actuator name="L_hip2_motor">
      <hardwareInterface>hardware_interface/EffortJointInterface</hardwareInterface>
      <mechanicalReduction>1</mechanicalReduction>
    </actuator>
  </transmission>
  <transmission name="L_thigh_tran">
    <type>transmission_interface/SimpleTransmission</type>
    <joint name="L_thigh_joint">
      <hardwareInterface>hardware_interface/EffortJointInterface</hardwareInterface>
    </joint>
    <actuator name="L_thigh_motor">
      <hardwareInterface>hardware_interface/EffortJointInterface</hardwareInterface>
      <mechanicalReduction>1</mechanicalReduction>
    </actuator>
  </transmission>
  <transmission name="L_calf_tran">
    <type>transmission_interface/SimpleTransmission</type>
    <joint name="L_calf_joint">
      <hardwareInterface>hardware_interface/EffortJointInterface</hardwareInterface>
    </joint>
    <actuator name="L_calf_motor">
      <hardwareInterface>hardware_interface/EffortJointInterface</hardwareInterface>
      <mechanicalReduction>1</mechanicalReduction>
    </actuator>
  </transmission>
  <transmission name="L_toe_tran">
    <type>transmission_interface/SimpleTransmission</type>
    <joint name="L_toe_joint">
      <hardwareInterface>hardware_interface/EffortJointInterface</hardwareInterface>
    </joint>
    <actuator name="L_toe_motor">
      <hardwareInterface>hardware_interface/EffortJointInterface</hardwareInterface>
      <mechanicalReduction>1</mechanicalReduction>
    </actuator>
  </transmission>
  <joint name="R_hip_joint" type="revolute">
    <origin rpy="0 0 0" xyz="0.0 -0.047 -0.1265"/>
    <parent link="trunk"/>
    <child link="R_hip"/>
    <axis xyz="0 0 1"/>
    <dynamics damping="0.1" friction="0.1"/>
    <limit effort="33.5" lower="-0.2617993877991494" upper="0.2617993877991494" velocity="21"/>
  </joint>
  <link name="R_hip">
    <visual>
      <origin rpy="0 0 0" xyz="0 0 0"/>
      <geometry>
        <mesh filename="package://my_biped_description/meshes/R_hip1.STL" scale="1 1 1"/>
      </geometry>
      <material name="orange"/>
    </visual>
    <collision>
      <origin rpy="0 0 0" xyz="0.015 0.0 -0.002"/>
      <geometry>
        <box size="0.0001 0.0001 0.0001"/>
      </geometry>
    </collision>
    <inertial>
      <origin rpy="0 0 0" xyz="0.025109 -0.002292 -0.024732"/>
      <mass value="0.224"/>
      <inertia ixx="2.104e-06" ixy="0.0" ixz="0.0" iyy="5.354e-06" iyz="0.0" izz="7.416e-06"/>
    </inertial>
  </link>
  <!--this link is only for motor mass&colllision-->
  <joint name="R_hip_trans_joint" type="fixed">
    <origin rpy="0 0 0" xyz="0.079 -0.015 -0.0705"/>
    <parent link="R_hip"/>
    <child link="R_hip_trans"/>
  </joint>
   --&gt;


  <link name="R_hip_trans">
    <collision>
      <origin rpy="0 1.5707963267948966 0" xyz="0 0 0"/>
      <geometry>
        <cylinder length="0.04" radius="0.045"/>
      </geometry>
    </collision>
    <inertial>
      <origin rpy="0 0 0" xyz="0 0 0"/>
      <mass value="0.65"/>
      <inertia ixx="0.00043875" ixy="0.0" ixz="0.0" iyy="0.00043875" iyz="0.0" izz="0.000658125"/>
    </inertial>
  </link>
  <joint name="R_hip2_joint" type="revolute">
    <origin rpy="0 0 0" xyz="0.0465 -0.015 -0.0705"/>
    <parent link="R_hip"/>
    <child link="R_hip2"/>
    <axis xyz="1 0 0"/>
    <dynamics damping="0.1" friction="0.1"/>
    <limit effort="33.5" lower="-0.2617993877991494" upper="0.5235987755982988" velocity="21"/>
  </joint>
  <link name="R_hip2">
    <visual>
      <origin rpy="0 0 0" xyz="0 0 0"/>
      <geometry>
        <mesh filename="package://my_biped_description/meshes/R_hip2.STL" scale="1 1 1"/>
      </geometry>
      <material name="red"/>
    </visual>
    <collision>
      <origin rpy="0 0 0" xyz="-0.1 0 0"/>
      <geometry>
        <box size="1e-05 1e-05 1e-05"/>
      </geometry>
    </collision>
    <inertial>
      <origin rpy="0 0 0" xyz="-0.033217 -0.010231 0"/>
      <mass value="0.095"/>
      <inertia ixx="5.1083e-05" ixy="0.0" ixz="0.0" iyy="1.39825e-05" iyz="0.0" izz="9.3473e-05"/>
    </inertial>
  </link>
  <!--this link is only for collision-->
  <joint name="R_hip2_trans_joint" type="fixed">
    <origin rpy="0 0 0" xyz="-0.06 0.015 0.0"/>
    <parent link="R_hip2"/>
    <child link="R_hip2_trans"/>
  </joint>
  <link name="R_hip2_trans">
    <collision>
      <origin rpy="-1.5707963267948966 0 0" xyz="0 0 0"/>
      <geometry>
        <cylinder length="0.04" radius="0.045"/>
      </geometry>
    </collision>
    <inertial>
      <origin rpy="-1.5707963267948966 0 0" xyz="0 0 0"/>
      <mass value="0.65"/>
      <inertia ixx="0.00043875" ixy="0.0" ixz="0.0" iyy="0.00043875" iyz="0.0" izz="0.000658125"/>
    </inertial>
  </link>
  <joint name="R_thigh_joint" type="revolute">
    <origin rpy="0 0.9424777960769379 0" xyz="-0.06 -0.018 0"/>
    <parent link="R_hip2"/>
    <child link="R_thigh"/>
    <axis xyz="0 1 0"/>
    <joint_properties damping="0.1" friction="0.1"/>
    <!-- <limit effort="${thigh_torque_max}" velocity="${thigh_velocity_max}"/> -->
    <limit effort="33.5" lower="-3.14" upper="3.14" velocity="21"/>
  </joint>
  <link name="R_thigh">
    <visual>
      <origin rpy="0 0 0" xyz="0 0 0"/>
      <geometry>
        <mesh filename="package://my_biped_description/meshes/R_thigh.STL" scale="1 1 1"/>
        <!-- <mesh filename="package://my_biped_description/meshes_new/right_thigh_link.STL" scale="1 1 1"/> -->
      </geometry>
      <material name="white"/>
    </visual>
    <collision>
      <origin rpy="0 0 0" xyz="0.0 -0.0175 -0.09"/>
      <geometry>
        <box size="0.06 0.035 0.18"/>
      </geometry>
    </collision>
    <inertial>
      <origin rpy="0 0 0" xyz="-0.000147 -0.01991 -0.081117"/>
      <mass value="0.642"/>
      <inertia ixx="0.004437615" ixy="0.0" ixz="0.0" iyy="0.004788512" iyz="0.0" izz="0.000661818"/>
    </inertial>
  </link>
  <!--this link is only for collision-->
  <joint name="R_thigh1_trans_joint" type="fixed">
    <origin rpy="0 0 0" xyz="0.0 -0.0625 0.0"/>
    <parent link="R_thigh"/>
    <child link="R_thigh1_trans"/>
  </joint>
    --&gt;


  <link name="R_thigh1_trans">
    <collision>
      <origin rpy="-1.5707963267948966 0 0" xyz="0 0 0"/>
      <geometry>
        <cylinder length="0.04" radius="0.045"/>
      </geometry>
    </collision>
    <inertial>
      <origin rpy="-1.5707963267948966 0 0" xyz="0 0 0"/>
      <mass value="0.65"/>
      <inertia ixx="0.00043875" ixy="0.0" ixz="0.0" iyy="0.00043875" iyz="0.0" izz="0.000658125"/>
    </inertial>
  </link>
  <!--this link is only for collision-->
  <joint name="R_thigh2_trans_joint" type="fixed">
    <origin rpy="0 0 0" xyz="0.0 0.0225 -0.097"/>
    <parent link="R_thigh"/>
    <child link="R_thigh2_trans"/>
  </joint>
  <link name="R_thigh2_trans">
    <collision>
      <origin rpy="-1.5707963267948966 0 0" xyz="0 0 0"/>
      <geometry>
        <cylinder length="0.04" radius="0.045"/>
      </geometry>
    </collision>
    <inertial>
      <origin rpy="-1.5707963267948966 0 0" xyz="0 0 0"/>
      <mass value="0.65"/>
      <inertia ixx="0.00043875" ixy="0.0" ixz="0.0" iyy="0.00043875" iyz="0.0" izz="0.000658125"/>
    </inertial>
  </link>
  <joint name="R_calf_joint" type="revolute">
    <origin rpy="0 -1.8849555921538759 0" xyz="0.0 0.0 -0.22"/>
    <parent link="R_thigh"/>
    <child link="R_calf"/>
    <axis xyz="0 1 0"/>
    <joint_properties damping="0.1" friction="0.1"/>
    <!-- <limit effort="${calf_torque_max}" velocity="${calf_velocity_max}"/> -->
    <limit effort="33.5" lower="-3.14" upper="3.14" velocity="21"/>
  </joint>
  <link name="R_calf">
    <visual>
      <origin rpy="0 0 0" xyz="0 0 0"/>
      <geometry>
        <mesh filename="package://my_biped_description/meshes/R_calf.STL" scale="1 1 1"/>
      </geometry>
      <material name="orange"/>
    </visual>
    <collision>
      <origin rpy="0 0 0" xyz="0.0 -0.02 -0.11"/>
      <geometry>
        <cylinder length="0.2" radius="0.015"/>
      </geometry>
    </collision>
    <inertial>
      <origin rpy="0 0 0" xyz="0.0 -0.020417 -0.1141"/>
      <mass value="0.303"/>
      <inertia ixx="0.001911" ixy="0.0" ixz="0.0" iyy="0.00191038" iyz="0.0" izz="6.8352e-05"/>
    </inertial>
  </link>
  <joint name="R_toe_joint" type="revolute">
    <origin rpy="0 0.9424777960769379 0" xyz="0.0 -0.0 -0.22"/>
    <parent link="R_calf"/>
    <child link="R_toe"/>
    <axis xyz="0 1 0"/>
    <joint_properties damping="0.1" friction="0.1"/>
    <!-- <limit effort="${toe_torque_max}" velocity="${toe_velocity_max}"/> -->
    <limit effort="33.5" lower="-1.4" upper="1.4" velocity="21"/>
  </joint>
  <link name="R_toe">
    <visual>
      <origin rpy="0 0 0" xyz="0 0 0"/>
      <geometry>
        <mesh filename="package://my_biped_description/meshes/R_foot.STL" scale="1 1 1"/>
      </geometry>
      <material name="red"/>
    </visual>
    <collision>
      <origin rpy="0 0 0" xyz="0.01 -0.0194 -0.02"/>
      <geometry>
        <box size="0.15 0.02 0.04"/>
      </geometry>
    </collision>
    <inertial>
      <origin rpy="0 0 0" xyz="0.010569 -0.017949 -0.017118"/>
      <mass value="0.214"/>
      <inertia ixx="5.7298e-05" ixy="0.0" ixz="0.0" iyy="0.000290752" iyz="0.0" izz="0.000249491"/>
    </inertial>
  </link>
  <transmission name="R_hip_tran">
    <type>transmission_interface/SimpleTransmission</type>
    <joint name="R_hip_joint">
      <hardwareInterface>hardware_interface/EffortJointInterface</hardwareInterface>
    </joint>
    <actuator name="R_hip_motor">
      <hardwareInterface>hardware_interface/EffortJointInterface</hardwareInterface>
      <mechanicalReduction>1</mechanicalReduction>
    </actuator>
  </transmission>
  <transmission name="R_hip2_tran">
    <type>transmission_interface/SimpleTransmission</type>
    <joint name="R_hip2_joint">
      <hardwareInterface>hardware_interface/EffortJointInterface</hardwareInterface>
    </joint>
    <actuator name="R_hip2_motor">
      <hardwareInterface>hardware_interface/EffortJointInterface</hardwareInterface>
      <mechanicalReduction>1</mechanicalReduction>
    </actuator>
  </transmission>
  <transmission name="R_thigh_tran">
    <type>transmission_interface/SimpleTransmission</type>
    <joint name="R_thigh_joint">
      <hardwareInterface>hardware_interface/EffortJointInterface</hardwareInterface>
    </joint>
    <actuator name="R_thigh_motor">
      <hardwareInterface>hardware_interface/EffortJointInterface</hardwareInterface>
      <mechanicalReduction>1</mechanicalReduction>
    </actuator>
  </transmission>
  <transmission name="R_calf_tran">
    <type>transmission_interface/SimpleTransmission</type>
    <joint name="R_calf_joint">
      <hardwareInterface>hardware_interface/EffortJointInterface</hardwareInterface>
    </joint>
    <actuator name="R_calf_motor">
      <hardwareInterface>hardware_interface/EffortJointInterface</hardwareInterface>
      <mechanicalReduction>1</mechanicalReduction>
    </actuator>
  </transmission>
  <transmission name="R_toe_tran">
    <type>transmission_interface/SimpleTransmission</type>
    <joint name="R_toe_joint">
      <hardwareInterface>hardware_interface/EffortJointInterface</hardwareInterface>
    </joint>
    <actuator name="R_toe_motor">
      <hardwareInterface>hardware_interface/EffortJointInterface</hardwareInterface>
      <mechanicalReduction>1</mechanicalReduction>
    </actuator>
  </transmission>
</robot>
